2025-04-10 13:41:46,093 INFO: Microblog startup [in /Users/colewissink/Documents/Comp 205/comp-205-BeatLink/app/__init__.py:48]
2025-04-10 13:42:34,777 INFO: Microblog startup [in /Users/colewissink/Documents/Comp 205/comp-205-BeatLink/app/__init__.py:48]
2025-04-14 11:32:32,000 INFO: Microblog startup [in /Users/colewissink/Documents/Comp 205/comp-205-BeatLink/app/__init__.py:48]
2025-04-14 11:34:06,988 INFO: Microblog startup [in /Users/colewissink/Documents/Comp 205/comp-205-BeatLink/app/__init__.py:48]
2025-04-14 11:34:23,549 ERROR: Exception on /register [POST] [in /Users/colewissink/Documents/Comp 205/comp-205-BeatLink/beatlink/lib/python3.12/site-packages/flask/app.py:875]
Traceback (most recent call last):
  File "/Users/colewissink/Documents/Comp 205/comp-205-BeatLink/beatlink/lib/python3.12/site-packages/sqlalchemy/engine/base.py", line 1964, in _exec_single_context
    self.dialect.do_execute(
  File "/Users/colewissink/Documents/Comp 205/comp-205-BeatLink/beatlink/lib/python3.12/site-packages/sqlalchemy/engine/default.py", line 945, in do_execute
    cursor.execute(statement, parameters)
sqlite3.OperationalError: no such column: user.spotify_id

The above exception was the direct cause of the following exception:

Traceback (most recent call last):
  File "/Users/colewissink/Documents/Comp 205/comp-205-BeatLink/beatlink/lib/python3.12/site-packages/flask/app.py", line 1511, in wsgi_app
    response = self.full_dispatch_request()
               ^^^^^^^^^^^^^^^^^^^^^^^^^^^^
  File "/Users/colewissink/Documents/Comp 205/comp-205-BeatLink/beatlink/lib/python3.12/site-packages/flask/app.py", line 919, in full_dispatch_request
    rv = self.handle_user_exception(e)
         ^^^^^^^^^^^^^^^^^^^^^^^^^^^^^
  File "/Users/colewissink/Documents/Comp 205/comp-205-BeatLink/beatlink/lib/python3.12/site-packages/flask/app.py", line 917, in full_dispatch_request
    rv = self.dispatch_request()
         ^^^^^^^^^^^^^^^^^^^^^^^
  File "/Users/colewissink/Documents/Comp 205/comp-205-BeatLink/beatlink/lib/python3.12/site-packages/flask/app.py", line 902, in dispatch_request
    return self.ensure_sync(self.view_functions[rule.endpoint])(**view_args)  # type: ignore[no-any-return]
           ^^^^^^^^^^^^^^^^^^^^^^^^^^^^^^^^^^^^^^^^^^^^^^^^^^^^^^^^^^^^^^^^^
  File "/Users/colewissink/Documents/Comp 205/comp-205-BeatLink/app/routes.py", line 91, in register
    if form.validate_on_submit():
       ^^^^^^^^^^^^^^^^^^^^^^^^^
  File "/Users/colewissink/Documents/Comp 205/comp-205-BeatLink/beatlink/lib/python3.12/site-packages/flask_wtf/form.py", line 86, in validate_on_submit
    return self.is_submitted() and self.validate(extra_validators=extra_validators)
                                   ^^^^^^^^^^^^^^^^^^^^^^^^^^^^^^^^^^^^^^^^^^^^^^^^
  File "/Users/colewissink/Documents/Comp 205/comp-205-BeatLink/beatlink/lib/python3.12/site-packages/wtforms/form.py", line 330, in validate
    return super().validate(extra)
           ^^^^^^^^^^^^^^^^^^^^^^^
  File "/Users/colewissink/Documents/Comp 205/comp-205-BeatLink/beatlink/lib/python3.12/site-packages/wtforms/form.py", line 147, in validate
    if not field.validate(self, extra):
           ^^^^^^^^^^^^^^^^^^^^^^^^^^^
  File "/Users/colewissink/Documents/Comp 205/comp-205-BeatLink/beatlink/lib/python3.12/site-packages/wtforms/fields/core.py", line 234, in validate
    stop_validation = self._run_validation_chain(form, chain)
                      ^^^^^^^^^^^^^^^^^^^^^^^^^^^^^^^^^^^^^^^
  File "/Users/colewissink/Documents/Comp 205/comp-205-BeatLink/beatlink/lib/python3.12/site-packages/wtforms/fields/core.py", line 254, in _run_validation_chain
    validator(form, self)
  File "/Users/colewissink/Documents/Comp 205/comp-205-BeatLink/app/forms.py", line 27, in validate_username
    user = db.session.scalar(sa.select(User).where(
           ^^^^^^^^^^^^^^^^^^^^^^^^^^^^^^^^^^^^^^^^
  File "/Users/colewissink/Documents/Comp 205/comp-205-BeatLink/beatlink/lib/python3.12/site-packages/sqlalchemy/orm/scoping.py", line 1841, in scalar
    return self._proxied.scalar(
           ^^^^^^^^^^^^^^^^^^^^^
  File "/Users/colewissink/Documents/Comp 205/comp-205-BeatLink/beatlink/lib/python3.12/site-packages/sqlalchemy/orm/session.py", line 2413, in scalar
    return self._execute_internal(
           ^^^^^^^^^^^^^^^^^^^^^^^
  File "/Users/colewissink/Documents/Comp 205/comp-205-BeatLink/beatlink/lib/python3.12/site-packages/sqlalchemy/orm/session.py", line 2251, in _execute_internal
    result: Result[Any] = compile_state_cls.orm_execute_statement(
                          ^^^^^^^^^^^^^^^^^^^^^^^^^^^^^^^^^^^^^^^^
  File "/Users/colewissink/Documents/Comp 205/comp-205-BeatLink/beatlink/lib/python3.12/site-packages/sqlalchemy/orm/context.py", line 306, in orm_execute_statement
    result = conn.execute(
             ^^^^^^^^^^^^^
  File "/Users/colewissink/Documents/Comp 205/comp-205-BeatLink/beatlink/lib/python3.12/site-packages/sqlalchemy/engine/base.py", line 1416, in execute
    return meth(
           ^^^^^
  File "/Users/colewissink/Documents/Comp 205/comp-205-BeatLink/beatlink/lib/python3.12/site-packages/sqlalchemy/sql/elements.py", line 523, in _execute_on_connection
    return connection._execute_clauseelement(
           ^^^^^^^^^^^^^^^^^^^^^^^^^^^^^^^^^^
  File "/Users/colewissink/Documents/Comp 205/comp-205-BeatLink/beatlink/lib/python3.12/site-packages/sqlalchemy/engine/base.py", line 1638, in _execute_clauseelement
    ret = self._execute_context(
          ^^^^^^^^^^^^^^^^^^^^^^
  File "/Users/colewissink/Documents/Comp 205/comp-205-BeatLink/beatlink/lib/python3.12/site-packages/sqlalchemy/engine/base.py", line 1843, in _execute_context
    return self._exec_single_context(
           ^^^^^^^^^^^^^^^^^^^^^^^^^^
  File "/Users/colewissink/Documents/Comp 205/comp-205-BeatLink/beatlink/lib/python3.12/site-packages/sqlalchemy/engine/base.py", line 1983, in _exec_single_context
    self._handle_dbapi_exception(
  File "/Users/colewissink/Documents/Comp 205/comp-205-BeatLink/beatlink/lib/python3.12/site-packages/sqlalchemy/engine/base.py", line 2352, in _handle_dbapi_exception
    raise sqlalchemy_exception.with_traceback(exc_info[2]) from e
  File "/Users/colewissink/Documents/Comp 205/comp-205-BeatLink/beatlink/lib/python3.12/site-packages/sqlalchemy/engine/base.py", line 1964, in _exec_single_context
    self.dialect.do_execute(
  File "/Users/colewissink/Documents/Comp 205/comp-205-BeatLink/beatlink/lib/python3.12/site-packages/sqlalchemy/engine/default.py", line 945, in do_execute
    cursor.execute(statement, parameters)
sqlalchemy.exc.OperationalError: (sqlite3.OperationalError) no such column: user.spotify_id
[SQL: SELECT user.id, user.username, user.email, user.password_hash, user.about_me, user.last_seen, user.spotify_id, user.spotify_access_token, user.spotify_refresh_token, user.spotify_token_expires 
FROM user 
WHERE user.username = ?]
[parameters: ('coeworl',)]
(Background on this error at: https://sqlalche.me/e/20/e3q8)
2025-04-14 11:38:13,121 INFO: Microblog startup [in /Users/colewissink/Documents/Comp 205/comp-205-BeatLink/app/__init__.py:48]
2025-04-14 11:39:20,365 INFO: Microblog startup [in /Users/colewissink/Documents/Comp 205/comp-205-BeatLink/app/__init__.py:48]
2025-04-14 11:41:31,936 INFO: Microblog startup [in /Users/colewissink/Documents/Comp 205/comp-205-BeatLink/app/__init__.py:48]
2025-04-14 11:43:17,683 INFO: Microblog startup [in /Users/colewissink/Documents/Comp 205/comp-205-BeatLink/app/__init__.py:48]
